INFO:root:Fizzbuzz api started...
INFO:root:database connexion up
INFO:root:swagger available
INFO:root:add fizzbuzz route
INFO:root:add metrics route
INFO:werkzeug: * Running on http://127.0.0.1:5000/ (Press CTRL+C to quit)
INFO:werkzeug:127.0.0.1 - - [27/Oct/2020 19:34:34] "[35m[1mPOST /v1/fizzbuzz?int1=3&int2=5&limit=15&str1=fizz&str2=buzz HTTP/1.1[0m" 500 -
ERROR:werkzeug:Error on request:
Traceback (most recent call last):
  File "/Users/olivier/Dev/lbc/f2/env/lib/python3.8/site-packages/sqlalchemy/engine/base.py", line 1276, in _execute_context
    self.dialect.do_execute(
  File "/Users/olivier/Dev/lbc/f2/env/lib/python3.8/site-packages/sqlalchemy/engine/default.py", line 593, in do_execute
    cursor.execute(statement, parameters)
sqlite3.OperationalError: no such table: fizzbuzz

The above exception was the direct cause of the following exception:

Traceback (most recent call last):
  File "/Users/olivier/Dev/lbc/f2/env/lib/python3.8/site-packages/werkzeug/serving.py", line 323, in run_wsgi
    execute(self.server.app)
  File "/Users/olivier/Dev/lbc/f2/env/lib/python3.8/site-packages/werkzeug/serving.py", line 312, in execute
    application_iter = app(environ, start_response)
  File "/Users/olivier/Dev/lbc/f2/env/lib/python3.8/site-packages/flask/app.py", line 2464, in __call__
    return self.wsgi_app(environ, start_response)
  File "/Users/olivier/Dev/lbc/f2/env/lib/python3.8/site-packages/flask/app.py", line 2450, in wsgi_app
    response = self.handle_exception(e)
  File "/Users/olivier/Dev/lbc/f2/env/lib/python3.8/site-packages/flask_restful/__init__.py", line 272, in error_router
    return original_handler(e)
  File "/Users/olivier/Dev/lbc/f2/env/lib/python3.8/site-packages/flask/app.py", line 1867, in handle_exception
    reraise(exc_type, exc_value, tb)
  File "/Users/olivier/Dev/lbc/f2/env/lib/python3.8/site-packages/flask/_compat.py", line 38, in reraise
    raise value.with_traceback(tb)
  File "/Users/olivier/Dev/lbc/f2/env/lib/python3.8/site-packages/flask/app.py", line 2447, in wsgi_app
    response = self.full_dispatch_request()
  File "/Users/olivier/Dev/lbc/f2/env/lib/python3.8/site-packages/flask/app.py", line 1952, in full_dispatch_request
    rv = self.handle_user_exception(e)
  File "/Users/olivier/Dev/lbc/f2/env/lib/python3.8/site-packages/flask_restful/__init__.py", line 272, in error_router
    return original_handler(e)
  File "/Users/olivier/Dev/lbc/f2/env/lib/python3.8/site-packages/flask/app.py", line 1821, in handle_user_exception
    reraise(exc_type, exc_value, tb)
  File "/Users/olivier/Dev/lbc/f2/env/lib/python3.8/site-packages/flask/_compat.py", line 38, in reraise
    raise value.with_traceback(tb)
  File "/Users/olivier/Dev/lbc/f2/env/lib/python3.8/site-packages/flask/app.py", line 1950, in full_dispatch_request
    rv = self.dispatch_request()
  File "/Users/olivier/Dev/lbc/f2/env/lib/python3.8/site-packages/flask/app.py", line 1936, in dispatch_request
    return self.view_functions[rule.endpoint](**req.view_args)
  File "/Users/olivier/Dev/lbc/f2/env/lib/python3.8/site-packages/flask_restful/__init__.py", line 468, in wrapper
    resp = resource(*args, **kwargs)
  File "/Users/olivier/Dev/lbc/f2/env/lib/python3.8/site-packages/flask/views.py", line 89, in view
    return self.dispatch_request(*args, **kwargs)
  File "/Users/olivier/Dev/lbc/f2/env/lib/python3.8/site-packages/flask_restful/__init__.py", line 583, in dispatch_request
    resp = meth(*args, **kwargs)
  File "/Users/olivier/Dev/lbc/f2/FizzbuzzApi/endpoints/fizzbuzzEP.py", line 84, in post
    fzRq.insertUsersRequest(fzquery)
  File "/Users/olivier/Dev/lbc/f2/FizzbuzzApi/database/fizzBuzzRQ.py", line 31, in insertUsersRequest
    print(db.session.commit())
  File "/Users/olivier/Dev/lbc/f2/env/lib/python3.8/site-packages/sqlalchemy/orm/scoping.py", line 163, in do
    return getattr(self.registry(), name)(*args, **kwargs)
  File "/Users/olivier/Dev/lbc/f2/env/lib/python3.8/site-packages/sqlalchemy/orm/session.py", line 1042, in commit
    self.transaction.commit()
  File "/Users/olivier/Dev/lbc/f2/env/lib/python3.8/site-packages/sqlalchemy/orm/session.py", line 504, in commit
    self._prepare_impl()
  File "/Users/olivier/Dev/lbc/f2/env/lib/python3.8/site-packages/sqlalchemy/orm/session.py", line 483, in _prepare_impl
    self.session.flush()
  File "/Users/olivier/Dev/lbc/f2/env/lib/python3.8/site-packages/sqlalchemy/orm/session.py", line 2536, in flush
    self._flush(objects)
  File "/Users/olivier/Dev/lbc/f2/env/lib/python3.8/site-packages/sqlalchemy/orm/session.py", line 2678, in _flush
    transaction.rollback(_capture_exception=True)
  File "/Users/olivier/Dev/lbc/f2/env/lib/python3.8/site-packages/sqlalchemy/util/langhelpers.py", line 68, in __exit__
    compat.raise_(
  File "/Users/olivier/Dev/lbc/f2/env/lib/python3.8/site-packages/sqlalchemy/util/compat.py", line 182, in raise_
    raise exception
  File "/Users/olivier/Dev/lbc/f2/env/lib/python3.8/site-packages/sqlalchemy/orm/session.py", line 2638, in _flush
    flush_context.execute()
  File "/Users/olivier/Dev/lbc/f2/env/lib/python3.8/site-packages/sqlalchemy/orm/unitofwork.py", line 422, in execute
    rec.execute(self)
  File "/Users/olivier/Dev/lbc/f2/env/lib/python3.8/site-packages/sqlalchemy/orm/unitofwork.py", line 586, in execute
    persistence.save_obj(
  File "/Users/olivier/Dev/lbc/f2/env/lib/python3.8/site-packages/sqlalchemy/orm/persistence.py", line 239, in save_obj
    _emit_insert_statements(
  File "/Users/olivier/Dev/lbc/f2/env/lib/python3.8/site-packages/sqlalchemy/orm/persistence.py", line 1135, in _emit_insert_statements
    result = cached_connections[connection].execute(
  File "/Users/olivier/Dev/lbc/f2/env/lib/python3.8/site-packages/sqlalchemy/engine/base.py", line 1011, in execute
    return meth(self, multiparams, params)
  File "/Users/olivier/Dev/lbc/f2/env/lib/python3.8/site-packages/sqlalchemy/sql/elements.py", line 298, in _execute_on_connection
    return connection._execute_clauseelement(self, multiparams, params)
  File "/Users/olivier/Dev/lbc/f2/env/lib/python3.8/site-packages/sqlalchemy/engine/base.py", line 1124, in _execute_clauseelement
    ret = self._execute_context(
  File "/Users/olivier/Dev/lbc/f2/env/lib/python3.8/site-packages/sqlalchemy/engine/base.py", line 1316, in _execute_context
    self._handle_dbapi_exception(
  File "/Users/olivier/Dev/lbc/f2/env/lib/python3.8/site-packages/sqlalchemy/engine/base.py", line 1510, in _handle_dbapi_exception
    util.raise_(
  File "/Users/olivier/Dev/lbc/f2/env/lib/python3.8/site-packages/sqlalchemy/util/compat.py", line 182, in raise_
    raise exception
  File "/Users/olivier/Dev/lbc/f2/env/lib/python3.8/site-packages/sqlalchemy/engine/base.py", line 1276, in _execute_context
    self.dialect.do_execute(
  File "/Users/olivier/Dev/lbc/f2/env/lib/python3.8/site-packages/sqlalchemy/engine/default.py", line 593, in do_execute
    cursor.execute(statement, parameters)
sqlalchemy.exc.OperationalError: (sqlite3.OperationalError) no such table: fizzbuzz
[SQL: INSERT INTO fizzbuzz (int1, int2, mlimit, str1, str2) VALUES (?, ?, ?, ?, ?)]
[parameters: (3, 5, 15, 'fizz', 'buzz')]
(Background on this error at: http://sqlalche.me/e/13/e3q8)
INFO:werkzeug:127.0.0.1 - - [27/Oct/2020 19:34:52] "[35m[1mPOST /v1/fizzbuzz?int1=3&int2=5&limit=15&str1=fizz&str2=buzz HTTP/1.1[0m" 500 -
ERROR:werkzeug:Error on request:
Traceback (most recent call last):
  File "/Users/olivier/Dev/lbc/f2/env/lib/python3.8/site-packages/sqlalchemy/engine/base.py", line 1276, in _execute_context
    self.dialect.do_execute(
  File "/Users/olivier/Dev/lbc/f2/env/lib/python3.8/site-packages/sqlalchemy/engine/default.py", line 593, in do_execute
    cursor.execute(statement, parameters)
sqlite3.OperationalError: no such table: fizzbuzz

The above exception was the direct cause of the following exception:

Traceback (most recent call last):
  File "/Users/olivier/Dev/lbc/f2/env/lib/python3.8/site-packages/werkzeug/serving.py", line 323, in run_wsgi
    execute(self.server.app)
  File "/Users/olivier/Dev/lbc/f2/env/lib/python3.8/site-packages/werkzeug/serving.py", line 312, in execute
    application_iter = app(environ, start_response)
  File "/Users/olivier/Dev/lbc/f2/env/lib/python3.8/site-packages/flask/app.py", line 2464, in __call__
    return self.wsgi_app(environ, start_response)
  File "/Users/olivier/Dev/lbc/f2/env/lib/python3.8/site-packages/flask/app.py", line 2450, in wsgi_app
    response = self.handle_exception(e)
  File "/Users/olivier/Dev/lbc/f2/env/lib/python3.8/site-packages/flask_restful/__init__.py", line 272, in error_router
    return original_handler(e)
  File "/Users/olivier/Dev/lbc/f2/env/lib/python3.8/site-packages/flask/app.py", line 1867, in handle_exception
    reraise(exc_type, exc_value, tb)
  File "/Users/olivier/Dev/lbc/f2/env/lib/python3.8/site-packages/flask/_compat.py", line 38, in reraise
    raise value.with_traceback(tb)
  File "/Users/olivier/Dev/lbc/f2/env/lib/python3.8/site-packages/flask/app.py", line 2447, in wsgi_app
    response = self.full_dispatch_request()
  File "/Users/olivier/Dev/lbc/f2/env/lib/python3.8/site-packages/flask/app.py", line 1952, in full_dispatch_request
    rv = self.handle_user_exception(e)
  File "/Users/olivier/Dev/lbc/f2/env/lib/python3.8/site-packages/flask_restful/__init__.py", line 272, in error_router
    return original_handler(e)
  File "/Users/olivier/Dev/lbc/f2/env/lib/python3.8/site-packages/flask/app.py", line 1821, in handle_user_exception
    reraise(exc_type, exc_value, tb)
  File "/Users/olivier/Dev/lbc/f2/env/lib/python3.8/site-packages/flask/_compat.py", line 38, in reraise
    raise value.with_traceback(tb)
  File "/Users/olivier/Dev/lbc/f2/env/lib/python3.8/site-packages/flask/app.py", line 1950, in full_dispatch_request
    rv = self.dispatch_request()
  File "/Users/olivier/Dev/lbc/f2/env/lib/python3.8/site-packages/flask/app.py", line 1936, in dispatch_request
    return self.view_functions[rule.endpoint](**req.view_args)
  File "/Users/olivier/Dev/lbc/f2/env/lib/python3.8/site-packages/flask_restful/__init__.py", line 468, in wrapper
    resp = resource(*args, **kwargs)
  File "/Users/olivier/Dev/lbc/f2/env/lib/python3.8/site-packages/flask/views.py", line 89, in view
    return self.dispatch_request(*args, **kwargs)
  File "/Users/olivier/Dev/lbc/f2/env/lib/python3.8/site-packages/flask_restful/__init__.py", line 583, in dispatch_request
    resp = meth(*args, **kwargs)
  File "/Users/olivier/Dev/lbc/f2/FizzbuzzApi/endpoints/fizzbuzzEP.py", line 84, in post
    fzRq.insertUsersRequest(fzquery)
  File "/Users/olivier/Dev/lbc/f2/FizzbuzzApi/database/fizzBuzzRQ.py", line 31, in insertUsersRequest
    print(db.session.commit())
  File "/Users/olivier/Dev/lbc/f2/env/lib/python3.8/site-packages/sqlalchemy/orm/scoping.py", line 163, in do
    return getattr(self.registry(), name)(*args, **kwargs)
  File "/Users/olivier/Dev/lbc/f2/env/lib/python3.8/site-packages/sqlalchemy/orm/session.py", line 1042, in commit
    self.transaction.commit()
  File "/Users/olivier/Dev/lbc/f2/env/lib/python3.8/site-packages/sqlalchemy/orm/session.py", line 504, in commit
    self._prepare_impl()
  File "/Users/olivier/Dev/lbc/f2/env/lib/python3.8/site-packages/sqlalchemy/orm/session.py", line 483, in _prepare_impl
    self.session.flush()
  File "/Users/olivier/Dev/lbc/f2/env/lib/python3.8/site-packages/sqlalchemy/orm/session.py", line 2536, in flush
    self._flush(objects)
  File "/Users/olivier/Dev/lbc/f2/env/lib/python3.8/site-packages/sqlalchemy/orm/session.py", line 2678, in _flush
    transaction.rollback(_capture_exception=True)
  File "/Users/olivier/Dev/lbc/f2/env/lib/python3.8/site-packages/sqlalchemy/util/langhelpers.py", line 68, in __exit__
    compat.raise_(
  File "/Users/olivier/Dev/lbc/f2/env/lib/python3.8/site-packages/sqlalchemy/util/compat.py", line 182, in raise_
    raise exception
  File "/Users/olivier/Dev/lbc/f2/env/lib/python3.8/site-packages/sqlalchemy/orm/session.py", line 2638, in _flush
    flush_context.execute()
  File "/Users/olivier/Dev/lbc/f2/env/lib/python3.8/site-packages/sqlalchemy/orm/unitofwork.py", line 422, in execute
    rec.execute(self)
  File "/Users/olivier/Dev/lbc/f2/env/lib/python3.8/site-packages/sqlalchemy/orm/unitofwork.py", line 586, in execute
    persistence.save_obj(
  File "/Users/olivier/Dev/lbc/f2/env/lib/python3.8/site-packages/sqlalchemy/orm/persistence.py", line 239, in save_obj
    _emit_insert_statements(
  File "/Users/olivier/Dev/lbc/f2/env/lib/python3.8/site-packages/sqlalchemy/orm/persistence.py", line 1135, in _emit_insert_statements
    result = cached_connections[connection].execute(
  File "/Users/olivier/Dev/lbc/f2/env/lib/python3.8/site-packages/sqlalchemy/engine/base.py", line 1011, in execute
    return meth(self, multiparams, params)
  File "/Users/olivier/Dev/lbc/f2/env/lib/python3.8/site-packages/sqlalchemy/sql/elements.py", line 298, in _execute_on_connection
    return connection._execute_clauseelement(self, multiparams, params)
  File "/Users/olivier/Dev/lbc/f2/env/lib/python3.8/site-packages/sqlalchemy/engine/base.py", line 1124, in _execute_clauseelement
    ret = self._execute_context(
  File "/Users/olivier/Dev/lbc/f2/env/lib/python3.8/site-packages/sqlalchemy/engine/base.py", line 1316, in _execute_context
    self._handle_dbapi_exception(
  File "/Users/olivier/Dev/lbc/f2/env/lib/python3.8/site-packages/sqlalchemy/engine/base.py", line 1510, in _handle_dbapi_exception
    util.raise_(
  File "/Users/olivier/Dev/lbc/f2/env/lib/python3.8/site-packages/sqlalchemy/util/compat.py", line 182, in raise_
    raise exception
  File "/Users/olivier/Dev/lbc/f2/env/lib/python3.8/site-packages/sqlalchemy/engine/base.py", line 1276, in _execute_context
    self.dialect.do_execute(
  File "/Users/olivier/Dev/lbc/f2/env/lib/python3.8/site-packages/sqlalchemy/engine/default.py", line 593, in do_execute
    cursor.execute(statement, parameters)
sqlalchemy.exc.OperationalError: (sqlite3.OperationalError) no such table: fizzbuzz
[SQL: INSERT INTO fizzbuzz (int1, int2, mlimit, str1, str2) VALUES (?, ?, ?, ?, ?)]
[parameters: (3, 5, 15, 'fizz', 'buzz')]
(Background on this error at: http://sqlalche.me/e/13/e3q8)
INFO:root:Fizzbuzz api started...
INFO:root:database connexion up
INFO:root:swagger available
INFO:root:add fizzbuzz route
INFO:root:add metrics route
INFO:werkzeug: * Running on http://127.0.0.1:5000/ (Press CTRL+C to quit)
INFO:werkzeug:127.0.0.1 - - [27/Oct/2020 19:35:30] "[35m[1mPOST /v1/fizzbuzz?int1=3&int2=5&limit=15&str1=fizz&str2=buzz HTTP/1.1[0m" 500 -
ERROR:werkzeug:Error on request:
Traceback (most recent call last):
  File "/Users/olivier/Dev/lbc/f2/env/lib/python3.8/site-packages/sqlalchemy/engine/base.py", line 1276, in _execute_context
    self.dialect.do_execute(
  File "/Users/olivier/Dev/lbc/f2/env/lib/python3.8/site-packages/sqlalchemy/engine/default.py", line 593, in do_execute
    cursor.execute(statement, parameters)
sqlite3.OperationalError: no such table: fizzbuzz

The above exception was the direct cause of the following exception:

Traceback (most recent call last):
  File "/Users/olivier/Dev/lbc/f2/env/lib/python3.8/site-packages/werkzeug/serving.py", line 323, in run_wsgi
    execute(self.server.app)
  File "/Users/olivier/Dev/lbc/f2/env/lib/python3.8/site-packages/werkzeug/serving.py", line 312, in execute
    application_iter = app(environ, start_response)
  File "/Users/olivier/Dev/lbc/f2/env/lib/python3.8/site-packages/flask/app.py", line 2464, in __call__
    return self.wsgi_app(environ, start_response)
  File "/Users/olivier/Dev/lbc/f2/env/lib/python3.8/site-packages/flask/app.py", line 2450, in wsgi_app
    response = self.handle_exception(e)
  File "/Users/olivier/Dev/lbc/f2/env/lib/python3.8/site-packages/flask_restful/__init__.py", line 272, in error_router
    return original_handler(e)
  File "/Users/olivier/Dev/lbc/f2/env/lib/python3.8/site-packages/flask/app.py", line 1867, in handle_exception
    reraise(exc_type, exc_value, tb)
  File "/Users/olivier/Dev/lbc/f2/env/lib/python3.8/site-packages/flask/_compat.py", line 38, in reraise
    raise value.with_traceback(tb)
  File "/Users/olivier/Dev/lbc/f2/env/lib/python3.8/site-packages/flask/app.py", line 2447, in wsgi_app
    response = self.full_dispatch_request()
  File "/Users/olivier/Dev/lbc/f2/env/lib/python3.8/site-packages/flask/app.py", line 1952, in full_dispatch_request
    rv = self.handle_user_exception(e)
  File "/Users/olivier/Dev/lbc/f2/env/lib/python3.8/site-packages/flask_restful/__init__.py", line 272, in error_router
    return original_handler(e)
  File "/Users/olivier/Dev/lbc/f2/env/lib/python3.8/site-packages/flask/app.py", line 1821, in handle_user_exception
    reraise(exc_type, exc_value, tb)
  File "/Users/olivier/Dev/lbc/f2/env/lib/python3.8/site-packages/flask/_compat.py", line 38, in reraise
    raise value.with_traceback(tb)
  File "/Users/olivier/Dev/lbc/f2/env/lib/python3.8/site-packages/flask/app.py", line 1950, in full_dispatch_request
    rv = self.dispatch_request()
  File "/Users/olivier/Dev/lbc/f2/env/lib/python3.8/site-packages/flask/app.py", line 1936, in dispatch_request
    return self.view_functions[rule.endpoint](**req.view_args)
  File "/Users/olivier/Dev/lbc/f2/env/lib/python3.8/site-packages/flask_restful/__init__.py", line 468, in wrapper
    resp = resource(*args, **kwargs)
  File "/Users/olivier/Dev/lbc/f2/env/lib/python3.8/site-packages/flask/views.py", line 89, in view
    return self.dispatch_request(*args, **kwargs)
  File "/Users/olivier/Dev/lbc/f2/env/lib/python3.8/site-packages/flask_restful/__init__.py", line 583, in dispatch_request
    resp = meth(*args, **kwargs)
  File "/Users/olivier/Dev/lbc/f2/FizzbuzzApi/endpoints/fizzbuzzEP.py", line 84, in post
    fzRq.insertUsersRequest(fzquery)
  File "/Users/olivier/Dev/lbc/f2/FizzbuzzApi/database/fizzBuzzRQ.py", line 31, in insertUsersRequest
    db.session.commit()
  File "/Users/olivier/Dev/lbc/f2/env/lib/python3.8/site-packages/sqlalchemy/orm/scoping.py", line 163, in do
    return getattr(self.registry(), name)(*args, **kwargs)
  File "/Users/olivier/Dev/lbc/f2/env/lib/python3.8/site-packages/sqlalchemy/orm/session.py", line 1042, in commit
    self.transaction.commit()
  File "/Users/olivier/Dev/lbc/f2/env/lib/python3.8/site-packages/sqlalchemy/orm/session.py", line 504, in commit
    self._prepare_impl()
  File "/Users/olivier/Dev/lbc/f2/env/lib/python3.8/site-packages/sqlalchemy/orm/session.py", line 483, in _prepare_impl
    self.session.flush()
  File "/Users/olivier/Dev/lbc/f2/env/lib/python3.8/site-packages/sqlalchemy/orm/session.py", line 2536, in flush
    self._flush(objects)
  File "/Users/olivier/Dev/lbc/f2/env/lib/python3.8/site-packages/sqlalchemy/orm/session.py", line 2678, in _flush
    transaction.rollback(_capture_exception=True)
  File "/Users/olivier/Dev/lbc/f2/env/lib/python3.8/site-packages/sqlalchemy/util/langhelpers.py", line 68, in __exit__
    compat.raise_(
  File "/Users/olivier/Dev/lbc/f2/env/lib/python3.8/site-packages/sqlalchemy/util/compat.py", line 182, in raise_
    raise exception
  File "/Users/olivier/Dev/lbc/f2/env/lib/python3.8/site-packages/sqlalchemy/orm/session.py", line 2638, in _flush
    flush_context.execute()
  File "/Users/olivier/Dev/lbc/f2/env/lib/python3.8/site-packages/sqlalchemy/orm/unitofwork.py", line 422, in execute
    rec.execute(self)
  File "/Users/olivier/Dev/lbc/f2/env/lib/python3.8/site-packages/sqlalchemy/orm/unitofwork.py", line 586, in execute
    persistence.save_obj(
  File "/Users/olivier/Dev/lbc/f2/env/lib/python3.8/site-packages/sqlalchemy/orm/persistence.py", line 239, in save_obj
    _emit_insert_statements(
  File "/Users/olivier/Dev/lbc/f2/env/lib/python3.8/site-packages/sqlalchemy/orm/persistence.py", line 1135, in _emit_insert_statements
    result = cached_connections[connection].execute(
  File "/Users/olivier/Dev/lbc/f2/env/lib/python3.8/site-packages/sqlalchemy/engine/base.py", line 1011, in execute
    return meth(self, multiparams, params)
  File "/Users/olivier/Dev/lbc/f2/env/lib/python3.8/site-packages/sqlalchemy/sql/elements.py", line 298, in _execute_on_connection
    return connection._execute_clauseelement(self, multiparams, params)
  File "/Users/olivier/Dev/lbc/f2/env/lib/python3.8/site-packages/sqlalchemy/engine/base.py", line 1124, in _execute_clauseelement
    ret = self._execute_context(
  File "/Users/olivier/Dev/lbc/f2/env/lib/python3.8/site-packages/sqlalchemy/engine/base.py", line 1316, in _execute_context
    self._handle_dbapi_exception(
  File "/Users/olivier/Dev/lbc/f2/env/lib/python3.8/site-packages/sqlalchemy/engine/base.py", line 1510, in _handle_dbapi_exception
    util.raise_(
  File "/Users/olivier/Dev/lbc/f2/env/lib/python3.8/site-packages/sqlalchemy/util/compat.py", line 182, in raise_
    raise exception
  File "/Users/olivier/Dev/lbc/f2/env/lib/python3.8/site-packages/sqlalchemy/engine/base.py", line 1276, in _execute_context
    self.dialect.do_execute(
  File "/Users/olivier/Dev/lbc/f2/env/lib/python3.8/site-packages/sqlalchemy/engine/default.py", line 593, in do_execute
    cursor.execute(statement, parameters)
sqlalchemy.exc.OperationalError: (sqlite3.OperationalError) no such table: fizzbuzz
[SQL: INSERT INTO fizzbuzz (int1, int2, mlimit, str1, str2) VALUES (?, ?, ?, ?, ?)]
[parameters: (3, 5, 15, 'fizz', 'buzz')]
(Background on this error at: http://sqlalche.me/e/13/e3q8)
INFO:root:Fizzbuzz api started...
INFO:root:database connexion up
INFO:root:swagger available
INFO:root:add fizzbuzz route
INFO:root:add metrics route
INFO:werkzeug: * Running on http://127.0.0.1:5000/ (Press CTRL+C to quit)
INFO:werkzeug:127.0.0.1 - - [27/Oct/2020 19:36:07] "[35m[1mPOST /v1/fizzbuzz?int1=3&int2=5&limit=15&str1=fizz&str2=buzz HTTP/1.1[0m" 500 -
ERROR:werkzeug:Error on request:
Traceback (most recent call last):
  File "/Users/olivier/Dev/lbc/f2/env/lib/python3.8/site-packages/sqlalchemy/engine/base.py", line 1276, in _execute_context
    self.dialect.do_execute(
  File "/Users/olivier/Dev/lbc/f2/env/lib/python3.8/site-packages/sqlalchemy/engine/default.py", line 593, in do_execute
    cursor.execute(statement, parameters)
sqlite3.OperationalError: no such table: fizzbuzz

The above exception was the direct cause of the following exception:

Traceback (most recent call last):
  File "/Users/olivier/Dev/lbc/f2/env/lib/python3.8/site-packages/werkzeug/serving.py", line 323, in run_wsgi
    execute(self.server.app)
  File "/Users/olivier/Dev/lbc/f2/env/lib/python3.8/site-packages/werkzeug/serving.py", line 312, in execute
    application_iter = app(environ, start_response)
  File "/Users/olivier/Dev/lbc/f2/env/lib/python3.8/site-packages/flask/app.py", line 2464, in __call__
    return self.wsgi_app(environ, start_response)
  File "/Users/olivier/Dev/lbc/f2/env/lib/python3.8/site-packages/flask/app.py", line 2450, in wsgi_app
    response = self.handle_exception(e)
  File "/Users/olivier/Dev/lbc/f2/env/lib/python3.8/site-packages/flask_restful/__init__.py", line 272, in error_router
    return original_handler(e)
  File "/Users/olivier/Dev/lbc/f2/env/lib/python3.8/site-packages/flask/app.py", line 1867, in handle_exception
    reraise(exc_type, exc_value, tb)
  File "/Users/olivier/Dev/lbc/f2/env/lib/python3.8/site-packages/flask/_compat.py", line 38, in reraise
    raise value.with_traceback(tb)
  File "/Users/olivier/Dev/lbc/f2/env/lib/python3.8/site-packages/flask/app.py", line 2447, in wsgi_app
    response = self.full_dispatch_request()
  File "/Users/olivier/Dev/lbc/f2/env/lib/python3.8/site-packages/flask/app.py", line 1952, in full_dispatch_request
    rv = self.handle_user_exception(e)
  File "/Users/olivier/Dev/lbc/f2/env/lib/python3.8/site-packages/flask_restful/__init__.py", line 272, in error_router
    return original_handler(e)
  File "/Users/olivier/Dev/lbc/f2/env/lib/python3.8/site-packages/flask/app.py", line 1821, in handle_user_exception
    reraise(exc_type, exc_value, tb)
  File "/Users/olivier/Dev/lbc/f2/env/lib/python3.8/site-packages/flask/_compat.py", line 38, in reraise
    raise value.with_traceback(tb)
  File "/Users/olivier/Dev/lbc/f2/env/lib/python3.8/site-packages/flask/app.py", line 1950, in full_dispatch_request
    rv = self.dispatch_request()
  File "/Users/olivier/Dev/lbc/f2/env/lib/python3.8/site-packages/flask/app.py", line 1936, in dispatch_request
    return self.view_functions[rule.endpoint](**req.view_args)
  File "/Users/olivier/Dev/lbc/f2/env/lib/python3.8/site-packages/flask_restful/__init__.py", line 468, in wrapper
    resp = resource(*args, **kwargs)
  File "/Users/olivier/Dev/lbc/f2/env/lib/python3.8/site-packages/flask/views.py", line 89, in view
    return self.dispatch_request(*args, **kwargs)
  File "/Users/olivier/Dev/lbc/f2/env/lib/python3.8/site-packages/flask_restful/__init__.py", line 583, in dispatch_request
    resp = meth(*args, **kwargs)
  File "/Users/olivier/Dev/lbc/f2/FizzbuzzApi/endpoints/fizzbuzzEP.py", line 84, in post
    fzRq.insertUsersRequest(fzquery)
  File "/Users/olivier/Dev/lbc/f2/FizzbuzzApi/database/fizzBuzzRQ.py", line 31, in insertUsersRequest
    db.session.commit()
  File "/Users/olivier/Dev/lbc/f2/env/lib/python3.8/site-packages/sqlalchemy/orm/scoping.py", line 163, in do
    return getattr(self.registry(), name)(*args, **kwargs)
  File "/Users/olivier/Dev/lbc/f2/env/lib/python3.8/site-packages/sqlalchemy/orm/session.py", line 1042, in commit
    self.transaction.commit()
  File "/Users/olivier/Dev/lbc/f2/env/lib/python3.8/site-packages/sqlalchemy/orm/session.py", line 504, in commit
    self._prepare_impl()
  File "/Users/olivier/Dev/lbc/f2/env/lib/python3.8/site-packages/sqlalchemy/orm/session.py", line 483, in _prepare_impl
    self.session.flush()
  File "/Users/olivier/Dev/lbc/f2/env/lib/python3.8/site-packages/sqlalchemy/orm/session.py", line 2536, in flush
    self._flush(objects)
  File "/Users/olivier/Dev/lbc/f2/env/lib/python3.8/site-packages/sqlalchemy/orm/session.py", line 2678, in _flush
    transaction.rollback(_capture_exception=True)
  File "/Users/olivier/Dev/lbc/f2/env/lib/python3.8/site-packages/sqlalchemy/util/langhelpers.py", line 68, in __exit__
    compat.raise_(
  File "/Users/olivier/Dev/lbc/f2/env/lib/python3.8/site-packages/sqlalchemy/util/compat.py", line 182, in raise_
    raise exception
  File "/Users/olivier/Dev/lbc/f2/env/lib/python3.8/site-packages/sqlalchemy/orm/session.py", line 2638, in _flush
    flush_context.execute()
  File "/Users/olivier/Dev/lbc/f2/env/lib/python3.8/site-packages/sqlalchemy/orm/unitofwork.py", line 422, in execute
    rec.execute(self)
  File "/Users/olivier/Dev/lbc/f2/env/lib/python3.8/site-packages/sqlalchemy/orm/unitofwork.py", line 586, in execute
    persistence.save_obj(
  File "/Users/olivier/Dev/lbc/f2/env/lib/python3.8/site-packages/sqlalchemy/orm/persistence.py", line 239, in save_obj
    _emit_insert_statements(
  File "/Users/olivier/Dev/lbc/f2/env/lib/python3.8/site-packages/sqlalchemy/orm/persistence.py", line 1135, in _emit_insert_statements
    result = cached_connections[connection].execute(
  File "/Users/olivier/Dev/lbc/f2/env/lib/python3.8/site-packages/sqlalchemy/engine/base.py", line 1011, in execute
    return meth(self, multiparams, params)
  File "/Users/olivier/Dev/lbc/f2/env/lib/python3.8/site-packages/sqlalchemy/sql/elements.py", line 298, in _execute_on_connection
    return connection._execute_clauseelement(self, multiparams, params)
  File "/Users/olivier/Dev/lbc/f2/env/lib/python3.8/site-packages/sqlalchemy/engine/base.py", line 1124, in _execute_clauseelement
    ret = self._execute_context(
  File "/Users/olivier/Dev/lbc/f2/env/lib/python3.8/site-packages/sqlalchemy/engine/base.py", line 1316, in _execute_context
    self._handle_dbapi_exception(
  File "/Users/olivier/Dev/lbc/f2/env/lib/python3.8/site-packages/sqlalchemy/engine/base.py", line 1510, in _handle_dbapi_exception
    util.raise_(
  File "/Users/olivier/Dev/lbc/f2/env/lib/python3.8/site-packages/sqlalchemy/util/compat.py", line 182, in raise_
    raise exception
  File "/Users/olivier/Dev/lbc/f2/env/lib/python3.8/site-packages/sqlalchemy/engine/base.py", line 1276, in _execute_context
    self.dialect.do_execute(
  File "/Users/olivier/Dev/lbc/f2/env/lib/python3.8/site-packages/sqlalchemy/engine/default.py", line 593, in do_execute
    cursor.execute(statement, parameters)
sqlalchemy.exc.OperationalError: (sqlite3.OperationalError) no such table: fizzbuzz
[SQL: INSERT INTO fizzbuzz (int1, int2, mlimit, str1, str2) VALUES (?, ?, ?, ?, ?)]
[parameters: (3, 5, 15, 'fizz', 'buzz')]
(Background on this error at: http://sqlalche.me/e/13/e3q8)
INFO:werkzeug:127.0.0.1 - - [27/Oct/2020 19:36:17] "[35m[1mGET /v1/metrics HTTP/1.1[0m" 500 -
ERROR:werkzeug:Error on request:
Traceback (most recent call last):
  File "/Users/olivier/Dev/lbc/f2/env/lib/python3.8/site-packages/sqlalchemy/engine/base.py", line 1276, in _execute_context
    self.dialect.do_execute(
  File "/Users/olivier/Dev/lbc/f2/env/lib/python3.8/site-packages/sqlalchemy/engine/default.py", line 593, in do_execute
    cursor.execute(statement, parameters)
sqlite3.OperationalError: no such table: fizzbuzz

The above exception was the direct cause of the following exception:

Traceback (most recent call last):
  File "/Users/olivier/Dev/lbc/f2/env/lib/python3.8/site-packages/werkzeug/serving.py", line 323, in run_wsgi
    execute(self.server.app)
  File "/Users/olivier/Dev/lbc/f2/env/lib/python3.8/site-packages/werkzeug/serving.py", line 312, in execute
    application_iter = app(environ, start_response)
  File "/Users/olivier/Dev/lbc/f2/env/lib/python3.8/site-packages/flask/app.py", line 2464, in __call__
    return self.wsgi_app(environ, start_response)
  File "/Users/olivier/Dev/lbc/f2/env/lib/python3.8/site-packages/flask/app.py", line 2450, in wsgi_app
    response = self.handle_exception(e)
  File "/Users/olivier/Dev/lbc/f2/env/lib/python3.8/site-packages/flask_restful/__init__.py", line 272, in error_router
    return original_handler(e)
  File "/Users/olivier/Dev/lbc/f2/env/lib/python3.8/site-packages/flask/app.py", line 1867, in handle_exception
    reraise(exc_type, exc_value, tb)
  File "/Users/olivier/Dev/lbc/f2/env/lib/python3.8/site-packages/flask/_compat.py", line 38, in reraise
    raise value.with_traceback(tb)
  File "/Users/olivier/Dev/lbc/f2/env/lib/python3.8/site-packages/flask/app.py", line 2447, in wsgi_app
    response = self.full_dispatch_request()
  File "/Users/olivier/Dev/lbc/f2/env/lib/python3.8/site-packages/flask/app.py", line 1952, in full_dispatch_request
    rv = self.handle_user_exception(e)
  File "/Users/olivier/Dev/lbc/f2/env/lib/python3.8/site-packages/flask_restful/__init__.py", line 272, in error_router
    return original_handler(e)
  File "/Users/olivier/Dev/lbc/f2/env/lib/python3.8/site-packages/flask/app.py", line 1821, in handle_user_exception
    reraise(exc_type, exc_value, tb)
  File "/Users/olivier/Dev/lbc/f2/env/lib/python3.8/site-packages/flask/_compat.py", line 38, in reraise
    raise value.with_traceback(tb)
  File "/Users/olivier/Dev/lbc/f2/env/lib/python3.8/site-packages/flask/app.py", line 1950, in full_dispatch_request
    rv = self.dispatch_request()
  File "/Users/olivier/Dev/lbc/f2/env/lib/python3.8/site-packages/flask/app.py", line 1936, in dispatch_request
    return self.view_functions[rule.endpoint](**req.view_args)
  File "/Users/olivier/Dev/lbc/f2/env/lib/python3.8/site-packages/flask_restful/__init__.py", line 468, in wrapper
    resp = resource(*args, **kwargs)
  File "/Users/olivier/Dev/lbc/f2/env/lib/python3.8/site-packages/flask/views.py", line 89, in view
    return self.dispatch_request(*args, **kwargs)
  File "/Users/olivier/Dev/lbc/f2/env/lib/python3.8/site-packages/flask_restful/__init__.py", line 583, in dispatch_request
    resp = meth(*args, **kwargs)
  File "/Users/olivier/Dev/lbc/f2/FizzbuzzApi/endpoints/metricsEP.py", line 32, in get
    numOfRequest,mostRequested = fzRq.getTopUsersRequests()
  File "/Users/olivier/Dev/lbc/f2/FizzbuzzApi/database/fizzBuzzRQ.py", line 44, in getTopUsersRequests
    result = db.session.query(cnt, FizzBuzzML.int1, FizzBuzzML.int2, FizzBuzzML.mlimit, FizzBuzzML.str1, FizzBuzzML.str2).\
  File "/Users/olivier/Dev/lbc/f2/env/lib/python3.8/site-packages/sqlalchemy/orm/query.py", line 3373, in all
    return list(self)
  File "/Users/olivier/Dev/lbc/f2/env/lib/python3.8/site-packages/sqlalchemy/orm/query.py", line 3535, in __iter__
    return self._execute_and_instances(context)
  File "/Users/olivier/Dev/lbc/f2/env/lib/python3.8/site-packages/sqlalchemy/orm/query.py", line 3560, in _execute_and_instances
    result = conn.execute(querycontext.statement, self._params)
  File "/Users/olivier/Dev/lbc/f2/env/lib/python3.8/site-packages/sqlalchemy/engine/base.py", line 1011, in execute
    return meth(self, multiparams, params)
  File "/Users/olivier/Dev/lbc/f2/env/lib/python3.8/site-packages/sqlalchemy/sql/elements.py", line 298, in _execute_on_connection
    return connection._execute_clauseelement(self, multiparams, params)
  File "/Users/olivier/Dev/lbc/f2/env/lib/python3.8/site-packages/sqlalchemy/engine/base.py", line 1124, in _execute_clauseelement
    ret = self._execute_context(
  File "/Users/olivier/Dev/lbc/f2/env/lib/python3.8/site-packages/sqlalchemy/engine/base.py", line 1316, in _execute_context
    self._handle_dbapi_exception(
  File "/Users/olivier/Dev/lbc/f2/env/lib/python3.8/site-packages/sqlalchemy/engine/base.py", line 1510, in _handle_dbapi_exception
    util.raise_(
  File "/Users/olivier/Dev/lbc/f2/env/lib/python3.8/site-packages/sqlalchemy/util/compat.py", line 182, in raise_
    raise exception
  File "/Users/olivier/Dev/lbc/f2/env/lib/python3.8/site-packages/sqlalchemy/engine/base.py", line 1276, in _execute_context
    self.dialect.do_execute(
  File "/Users/olivier/Dev/lbc/f2/env/lib/python3.8/site-packages/sqlalchemy/engine/default.py", line 593, in do_execute
    cursor.execute(statement, parameters)
sqlalchemy.exc.OperationalError: (sqlite3.OperationalError) no such table: fizzbuzz
[SQL: SELECT count(?) AS count_1, fizzbuzz.int1 AS fizzbuzz_int1, fizzbuzz.int2 AS fizzbuzz_int2, fizzbuzz.mlimit AS fizzbuzz_mlimit, fizzbuzz.str1 AS fizzbuzz_str1, fizzbuzz.str2 AS fizzbuzz_str2 
FROM fizzbuzz GROUP BY fizzbuzz.int1, fizzbuzz.int2, fizzbuzz.mlimit, fizzbuzz.str1, fizzbuzz.str2 ORDER BY count(?) DESC
 LIMIT ? OFFSET ?]
[parameters: ('*', '*', 1, 0)]
(Background on this error at: http://sqlalche.me/e/13/e3q8)
INFO:root:Fizzbuzz api started...
INFO:root:database connexion up
INFO:root:swagger available
INFO:root:add fizzbuzz route
INFO:root:add metrics route
INFO:werkzeug: * Running on http://127.0.0.1:5000/ (Press CTRL+C to quit)
INFO:root:Fizzbuzz api started...
INFO:root:database connexion up
INFO:root:swagger available
INFO:root:add fizzbuzz route
INFO:root:add metrics route
INFO:werkzeug: * Running on http://127.0.0.1:5000/ (Press CTRL+C to quit)
INFO:werkzeug: * Restarting with stat
INFO:root:Fizzbuzz api started...
INFO:root:database connexion up
INFO:root:swagger available
INFO:root:add fizzbuzz route
INFO:root:add metrics route
WARNING:werkzeug: * Debugger is active!
INFO:werkzeug: * Debugger PIN: 128-654-923
INFO:werkzeug:127.0.0.1 - - [27/Oct/2020 19:38:03] "[37mPOST /v1/fizzbuzz?int1=3&int2=5&limit=15&str1=fizz&str2=buzz HTTP/1.1[0m" 200 -
INFO:werkzeug: * Detected change in '/Users/olivier/Dev/lbc/f2/FizzbuzzApi/database/fizzBuzzRQ.py', reloading
INFO:werkzeug: * Restarting with stat
INFO:root:Fizzbuzz api started...
INFO:root:database connexion up
INFO:root:swagger available
INFO:root:add fizzbuzz route
INFO:root:add metrics route
WARNING:werkzeug: * Debugger is active!
INFO:werkzeug: * Debugger PIN: 128-654-923
INFO:root:Fizzbuzz api started...
INFO:root:database connexion up
INFO:root:swagger available
INFO:root:add fizzbuzz route
INFO:root:add metrics route
INFO:werkzeug: * Running on http://127.0.0.1:5000/ (Press CTRL+C to quit)
INFO:werkzeug: * Restarting with stat
INFO:root:Fizzbuzz api started...
INFO:root:database connexion up
INFO:root:swagger available
INFO:root:add fizzbuzz route
INFO:root:add metrics route
WARNING:werkzeug: * Debugger is active!
INFO:werkzeug: * Debugger PIN: 128-654-923
INFO:werkzeug:127.0.0.1 - - [27/Oct/2020 19:38:41] "[37mPOST /v1/fizzbuzz?int1=3&int2=5&limit=15&str1=fizz&str2=buzz HTTP/1.1[0m" 200 -
INFO:werkzeug: * Detected change in '/Users/olivier/Dev/lbc/f2/FizzbuzzApi/database/fizzBuzzRQ.py', reloading
INFO:werkzeug: * Restarting with stat
INFO:root:Fizzbuzz api started...
INFO:root:database connexion up
INFO:root:swagger available
INFO:root:add fizzbuzz route
INFO:root:add metrics route
WARNING:werkzeug: * Debugger is active!
INFO:werkzeug: * Debugger PIN: 128-654-923
INFO:werkzeug: * Detected change in '/Users/olivier/Dev/lbc/f2/FizzbuzzApi/database/fizzBuzzRQ.py', reloading
INFO:werkzeug: * Restarting with stat
INFO:root:Fizzbuzz api started...
INFO:root:database connexion up
INFO:root:swagger available
INFO:root:Fizzbuzz api started...
INFO:root:database connexion up
INFO:root:swagger available
INFO:root:Fizzbuzz api started...
INFO:root:database connexion up
INFO:root:swagger available
INFO:root:Fizzbuzz api started...
INFO:root:database connexion up
INFO:root:swagger available
INFO:root:add fizzbuzz route
INFO:root:add metrics route
INFO:werkzeug: * Running on http://127.0.0.1:5000/ (Press CTRL+C to quit)
INFO:werkzeug: * Restarting with stat
INFO:root:Fizzbuzz api started...
INFO:root:database connexion up
INFO:root:swagger available
INFO:root:add fizzbuzz route
INFO:root:add metrics route
WARNING:werkzeug: * Debugger is active!
INFO:werkzeug: * Debugger PIN: 128-654-923
INFO:root:Fizzbuzz api started...
INFO:root:database connexion up
INFO:root:swagger available
INFO:root:add fizzbuzz route
INFO:root:add metrics route
INFO:werkzeug: * Running on http://127.0.0.1:5000/ (Press CTRL+C to quit)
INFO:werkzeug: * Restarting with stat
INFO:root:Fizzbuzz api started...
INFO:root:database connexion up
INFO:root:swagger available
INFO:root:add fizzbuzz route
INFO:root:add metrics route
WARNING:werkzeug: * Debugger is active!
INFO:werkzeug: * Debugger PIN: 128-654-923
INFO:werkzeug:127.0.0.1 - - [27/Oct/2020 19:52:43] "[37mPOST /v1/fizzbuzz?int1=3&int2=5&limit=15&str1=fizz&str2=buzz HTTP/1.1[0m" 200 -
INFO:root:Fizzbuzz api started...
INFO:root:database connexion up
INFO:root:swagger available
INFO:root:add fizzbuzz route
INFO:root:add metrics route
INFO:root:Fizzbuzz api started...
INFO:root:database connexion up
INFO:root:swagger available
INFO:root:add fizzbuzz route
INFO:root:add metrics route
INFO:werkzeug: * Running on http://127.0.0.1:5000/ (Press CTRL+C to quit)
ERROR:root:Cannot read from database (sqlite3.OperationalError) no such table: fizzbuzz
[SQL: INSERT INTO fizzbuzz (int1, int2, mlimit, str1, str2) VALUES (?, ?, ?, ?, ?)]
[parameters: (3, 5, 15, 'fizz', 'buzz')]
(Background on this error at: http://sqlalche.me/e/13/e3q8)
INFO:werkzeug:127.0.0.1 - - [27/Oct/2020 19:58:19] "[37mPOST /v1/fizzbuzz?int1=3&int2=5&limit=15&str1=fizz&str2=buzz HTTP/1.1[0m" 200 -
ERROR:root:Cannot insert into database (sqlite3.OperationalError) no such table: fizzbuzz
[SQL: SELECT count(?) AS count_1, fizzbuzz.int1 AS fizzbuzz_int1, fizzbuzz.int2 AS fizzbuzz_int2, fizzbuzz.mlimit AS fizzbuzz_mlimit, fizzbuzz.str1 AS fizzbuzz_str1, fizzbuzz.str2 AS fizzbuzz_str2 
FROM fizzbuzz GROUP BY fizzbuzz.int1, fizzbuzz.int2, fizzbuzz.mlimit, fizzbuzz.str1, fizzbuzz.str2 ORDER BY count(?) DESC
 LIMIT ? OFFSET ?]
[parameters: ('*', '*', 1, 0)]
(Background on this error at: http://sqlalche.me/e/13/e3q8)
INFO:werkzeug:127.0.0.1 - - [27/Oct/2020 20:01:10] "[37mGET /v1/metrics HTTP/1.1[0m" 200 -
ERROR:root:Cannot insert into database (sqlite3.OperationalError) no such table: fizzbuzz
[SQL: SELECT count(?) AS count_1, fizzbuzz.int1 AS fizzbuzz_int1, fizzbuzz.int2 AS fizzbuzz_int2, fizzbuzz.mlimit AS fizzbuzz_mlimit, fizzbuzz.str1 AS fizzbuzz_str1, fizzbuzz.str2 AS fizzbuzz_str2 
FROM fizzbuzz GROUP BY fizzbuzz.int1, fizzbuzz.int2, fizzbuzz.mlimit, fizzbuzz.str1, fizzbuzz.str2 ORDER BY count(?) DESC
 LIMIT ? OFFSET ?]
[parameters: ('*', '*', 1, 0)]
(Background on this error at: http://sqlalche.me/e/13/e3q8)
INFO:werkzeug:127.0.0.1 - - [27/Oct/2020 20:01:27] "[37mGET /v1/metrics HTTP/1.1[0m" 200 -
INFO:root:Fizzbuzz api started...
INFO:root:database connexion up
INFO:root:swagger available
INFO:root:add fizzbuzz route
INFO:root:add metrics route
INFO:werkzeug: * Running on http://127.0.0.1:5000/ (Press CTRL+C to quit)
INFO:root:exiting fizzbuzz api
INFO:root:Fizzbuzz api started...
INFO:root:database connexion up
INFO:root:swagger available
INFO:root:add fizzbuzz route
INFO:root:add metrics route
ERROR:root:Cannot read from database (sqlite3.OperationalError) no such table: fizzbuzz
[SQL: SELECT count(?) AS count_1, fizzbuzz.int1 AS fizzbuzz_int1, fizzbuzz.int2 AS fizzbuzz_int2, fizzbuzz.mlimit AS fizzbuzz_mlimit, fizzbuzz.str1 AS fizzbuzz_str1, fizzbuzz.str2 AS fizzbuzz_str2 
FROM fizzbuzz GROUP BY fizzbuzz.int1, fizzbuzz.int2, fizzbuzz.mlimit, fizzbuzz.str1, fizzbuzz.str2 ORDER BY count(?) DESC
 LIMIT ? OFFSET ?]
[parameters: ('*', '*', 1, 0)]
(Background on this error at: http://sqlalche.me/e/13/e3q8)
ERROR:root:Cannot insert into database (sqlite3.OperationalError) no such table: fizzbuzz
[SQL: INSERT INTO fizzbuzz (int1, int2, mlimit, str1, str2) VALUES (?, ?, ?, ?, ?)]
[parameters: (1, 2, 3, 'un', 'deux')]
(Background on this error at: http://sqlalche.me/e/13/e3q8)
INFO:root:Fizzbuzz api started...
INFO:root:database connexion up
INFO:root:swagger available
INFO:root:add fizzbuzz route
INFO:root:add metrics route
ERROR:root:Cannot read from database (sqlite3.OperationalError) no such table: fizzbuzz
[SQL: SELECT count(?) AS count_1, fizzbuzz.int1 AS fizzbuzz_int1, fizzbuzz.int2 AS fizzbuzz_int2, fizzbuzz.mlimit AS fizzbuzz_mlimit, fizzbuzz.str1 AS fizzbuzz_str1, fizzbuzz.str2 AS fizzbuzz_str2 
FROM fizzbuzz GROUP BY fizzbuzz.int1, fizzbuzz.int2, fizzbuzz.mlimit, fizzbuzz.str1, fizzbuzz.str2 ORDER BY count(?) DESC
 LIMIT ? OFFSET ?]
[parameters: ('*', '*', 1, 0)]
(Background on this error at: http://sqlalche.me/e/13/e3q8)
ERROR:root:Cannot insert into database (sqlite3.OperationalError) no such table: fizzbuzz
[SQL: INSERT INTO fizzbuzz (int1, int2, mlimit, str1, str2) VALUES (?, ?, ?, ?, ?)]
[parameters: (1, 2, 3, 'un', 'deux')]
(Background on this error at: http://sqlalche.me/e/13/e3q8)
INFO:root:Fizzbuzz api started...
INFO:root:database connexion up
INFO:root:swagger available
INFO:root:add fizzbuzz route
INFO:root:add metrics route
ERROR:root:Cannot read from database (sqlite3.OperationalError) no such table: fizzbuzz
[SQL: SELECT count(?) AS count_1, fizzbuzz.int1 AS fizzbuzz_int1, fizzbuzz.int2 AS fizzbuzz_int2, fizzbuzz.mlimit AS fizzbuzz_mlimit, fizzbuzz.str1 AS fizzbuzz_str1, fizzbuzz.str2 AS fizzbuzz_str2 
FROM fizzbuzz GROUP BY fizzbuzz.int1, fizzbuzz.int2, fizzbuzz.mlimit, fizzbuzz.str1, fizzbuzz.str2 ORDER BY count(?) DESC
 LIMIT ? OFFSET ?]
[parameters: ('*', '*', 1, 0)]
(Background on this error at: http://sqlalche.me/e/13/e3q8)
ERROR:root:Cannot insert into database (sqlite3.OperationalError) no such table: fizzbuzz
[SQL: INSERT INTO fizzbuzz (int1, int2, mlimit, str1, str2) VALUES (?, ?, ?, ?, ?)]
[parameters: (1, 2, 3, 'un', 'deux')]
(Background on this error at: http://sqlalche.me/e/13/e3q8)
INFO:root:Fizzbuzz api started...
INFO:root:database connexion up
INFO:root:swagger available
INFO:root:add fizzbuzz route
INFO:root:add metrics route
ERROR:root:Cannot read from database (sqlite3.OperationalError) no such table: fizzbuzz
[SQL: SELECT count(?) AS count_1, fizzbuzz.int1 AS fizzbuzz_int1, fizzbuzz.int2 AS fizzbuzz_int2, fizzbuzz.mlimit AS fizzbuzz_mlimit, fizzbuzz.str1 AS fizzbuzz_str1, fizzbuzz.str2 AS fizzbuzz_str2 
FROM fizzbuzz GROUP BY fizzbuzz.int1, fizzbuzz.int2, fizzbuzz.mlimit, fizzbuzz.str1, fizzbuzz.str2 ORDER BY count(?) DESC
 LIMIT ? OFFSET ?]
[parameters: ('*', '*', 1, 0)]
(Background on this error at: http://sqlalche.me/e/13/e3q8)
ERROR:root:Cannot insert into database (sqlite3.OperationalError) no such table: fizzbuzz
[SQL: INSERT INTO fizzbuzz (int1, int2, mlimit, str1, str2) VALUES (?, ?, ?, ?, ?)]
[parameters: (1, 2, 3, 'un', 'deux')]
(Background on this error at: http://sqlalche.me/e/13/e3q8)
ERROR:root:Cannot insert into database This Session's transaction has been rolled back due to a previous exception during flush. To begin a new transaction with this Session, first issue Session.rollback(). Original exception was: (sqlite3.OperationalError) no such table: fizzbuzz
[SQL: INSERT INTO fizzbuzz (int1, int2, mlimit, str1, str2) VALUES (?, ?, ?, ?, ?)]
[parameters: (1, 2, 3, 'un', 'deux')]
(Background on this error at: http://sqlalche.me/e/13/e3q8) (Background on this error at: http://sqlalche.me/e/13/7s2a)
INFO:root:Fizzbuzz api started...
INFO:root:database connexion up
INFO:root:swagger available
INFO:root:add fizzbuzz route
INFO:root:add metrics route
ERROR:root:Cannot read from database (sqlite3.OperationalError) no such table: fizzbuzz
[SQL: SELECT count(?) AS count_1, fizzbuzz.int1 AS fizzbuzz_int1, fizzbuzz.int2 AS fizzbuzz_int2, fizzbuzz.mlimit AS fizzbuzz_mlimit, fizzbuzz.str1 AS fizzbuzz_str1, fizzbuzz.str2 AS fizzbuzz_str2 
FROM fizzbuzz GROUP BY fizzbuzz.int1, fizzbuzz.int2, fizzbuzz.mlimit, fizzbuzz.str1, fizzbuzz.str2 ORDER BY count(?) DESC
 LIMIT ? OFFSET ?]
[parameters: ('*', '*', 1, 0)]
(Background on this error at: http://sqlalche.me/e/13/e3q8)
ERROR:root:Cannot insert into database (sqlite3.OperationalError) no such table: fizzbuzz
[SQL: INSERT INTO fizzbuzz (int1, int2, mlimit, str1, str2) VALUES (?, ?, ?, ?, ?)]
[parameters: (1, 2, 3, 'un', 'deux')]
(Background on this error at: http://sqlalche.me/e/13/e3q8)
